[2024-11-03T17:07:17.302+0000] {local_task_job_runner.py:123} INFO - ::group::Pre task execution logs
[2024-11-03T17:07:17.310+0000] {taskinstance.py:2612} INFO - Dependencies all met for dep_context=non-requeueable deps ti=<TaskInstance: data_pipeline.clean_temp_task1 manual__2024-11-03T17:07:16.116727+00:00 [queued]>
[2024-11-03T17:07:17.313+0000] {taskinstance.py:2612} INFO - Dependencies all met for dep_context=requeueable deps ti=<TaskInstance: data_pipeline.clean_temp_task1 manual__2024-11-03T17:07:16.116727+00:00 [queued]>
[2024-11-03T17:07:17.314+0000] {taskinstance.py:2865} INFO - Starting attempt 1 of 3
[2024-11-03T17:07:17.320+0000] {taskinstance.py:2888} INFO - Executing <Task(PythonOperator): clean_temp_task1> on 2024-11-03 17:07:16.116727+00:00
[2024-11-03T17:07:17.323+0000] {warnings.py:112} WARNING - /home/***/.local/lib/python3.12/site-packages/***/task/task_runner/standard_task_runner.py:70: DeprecationWarning: This process (pid=305) is multi-threaded, use of fork() may lead to deadlocks in the child.
  pid = os.fork()

[2024-11-03T17:07:17.324+0000] {standard_task_runner.py:72} INFO - Started process 313 to run task
[2024-11-03T17:07:17.325+0000] {standard_task_runner.py:104} INFO - Running: ['***', 'tasks', 'run', 'data_pipeline', 'clean_temp_task1', 'manual__2024-11-03T17:07:16.116727+00:00', '--job-id', '36', '--raw', '--subdir', 'DAGS_FOLDER/***.py', '--cfg-path', '/tmp/tmpn2_h5dtz']
[2024-11-03T17:07:17.327+0000] {standard_task_runner.py:105} INFO - Job 36: Subtask clean_temp_task1
[2024-11-03T17:07:17.352+0000] {task_command.py:467} INFO - Running <TaskInstance: data_pipeline.clean_temp_task1 manual__2024-11-03T17:07:16.116727+00:00 [running]> on host 9ab0960d13ae
[2024-11-03T17:07:17.383+0000] {taskinstance.py:3131} INFO - Exporting env vars: AIRFLOW_CTX_DAG_OWNER='your_name' AIRFLOW_CTX_DAG_ID='data_pipeline' AIRFLOW_CTX_TASK_ID='clean_temp_task1' AIRFLOW_CTX_EXECUTION_DATE='2024-11-03T17:07:16.116727+00:00' AIRFLOW_CTX_TRY_NUMBER='1' AIRFLOW_CTX_DAG_RUN_ID='manual__2024-11-03T17:07:16.116727+00:00'
[2024-11-03T17:07:17.384+0000] {taskinstance.py:731} INFO - ::endgroup::
[2024-11-03T17:07:17.392+0000] {taskinstance.py:3310} ERROR - Task failed with exception
Traceback (most recent call last):
  File "/home/airflow/.local/lib/python3.12/site-packages/airflow/models/taskinstance.py", line 767, in _execute_task
    result = _execute_callable(context=context, **execute_callable_kwargs)
             ^^^^^^^^^^^^^^^^^^^^^^^^^^^^^^^^^^^^^^^^^^^^^^^^^^^^^^^^^^^^^
  File "/home/airflow/.local/lib/python3.12/site-packages/airflow/models/taskinstance.py", line 733, in _execute_callable
    return ExecutionCallableRunner(
           ^^^^^^^^^^^^^^^^^^^^^^^^
  File "/home/airflow/.local/lib/python3.12/site-packages/airflow/utils/operator_helpers.py", line 252, in run
    return self.func(*args, **kwargs)
           ^^^^^^^^^^^^^^^^^^^^^^^^^^
  File "/home/airflow/.local/lib/python3.12/site-packages/airflow/models/baseoperator.py", line 406, in wrapper
    return func(self, *args, **kwargs)
           ^^^^^^^^^^^^^^^^^^^^^^^^^^^
  File "/home/airflow/.local/lib/python3.12/site-packages/airflow/operators/python.py", line 238, in execute
    return_value = self.execute_callable()
                   ^^^^^^^^^^^^^^^^^^^^^^^
  File "/home/airflow/.local/lib/python3.12/site-packages/airflow/operators/python.py", line 256, in execute_callable
    return runner.run(*self.op_args, **self.op_kwargs)
           ^^^^^^^^^^^^^^^^^^^^^^^^^^^^^^^^^^^^^^^^^^^
  File "/home/airflow/.local/lib/python3.12/site-packages/airflow/utils/operator_helpers.py", line 252, in run
    return self.func(*args, **kwargs)
           ^^^^^^^^^^^^^^^^^^^^^^^^^^
  File "/opt/airflow/dags/src/download_data.py", line 68, in clean_temp1
    shutil.rmtree(folder_path)
  File "/usr/local/lib/python3.12/shutil.py", line 759, in rmtree
    _rmtree_safe_fd(stack, onexc)
  File "/usr/local/lib/python3.12/shutil.py", line 703, in _rmtree_safe_fd
    onexc(func, path, err)
  File "/usr/local/lib/python3.12/shutil.py", line 700, in _rmtree_safe_fd
    onexc(os.unlink, fullname, err)
  File "/usr/local/lib/python3.12/shutil.py", line 698, in _rmtree_safe_fd
    os.unlink(entry.name, dir_fd=topfd)
FileNotFoundError: [Errno 2] No such file or directory: 'Data/temp1'
[2024-11-03T17:07:17.403+0000] {taskinstance.py:1225} INFO - Marking task as UP_FOR_RETRY. dag_id=data_pipeline, task_id=clean_temp_task1, run_id=manual__2024-11-03T17:07:16.116727+00:00, execution_date=20241103T170716, start_date=20241103T170717, end_date=20241103T170717
[2024-11-03T17:07:17.410+0000] {taskinstance.py:340} INFO - ::group::Post task execution logs
[2024-11-03T17:07:17.410+0000] {standard_task_runner.py:124} ERROR - Failed to execute job 36 for task clean_temp_task1 ([Errno 2] No such file or directory: 'Data/temp1'; 313)
Traceback (most recent call last):
  File "/home/airflow/.local/lib/python3.12/site-packages/airflow/task/task_runner/standard_task_runner.py", line 117, in _start_by_fork
    ret = args.func(args, dag=self.dag)
          ^^^^^^^^^^^^^^^^^^^^^^^^^^^^^
  File "/home/airflow/.local/lib/python3.12/site-packages/airflow/cli/cli_config.py", line 49, in command
    return func(*args, **kwargs)
           ^^^^^^^^^^^^^^^^^^^^^
  File "/home/airflow/.local/lib/python3.12/site-packages/airflow/utils/cli.py", line 115, in wrapper
    return f(*args, **kwargs)
           ^^^^^^^^^^^^^^^^^^
  File "/home/airflow/.local/lib/python3.12/site-packages/airflow/cli/commands/task_command.py", line 483, in task_run
    task_return_code = _run_task_by_selected_method(args, _dag, ti)
                       ^^^^^^^^^^^^^^^^^^^^^^^^^^^^^^^^^^^^^^^^^^^^
  File "/home/airflow/.local/lib/python3.12/site-packages/airflow/cli/commands/task_command.py", line 256, in _run_task_by_selected_method
    return _run_raw_task(args, ti)
           ^^^^^^^^^^^^^^^^^^^^^^^
  File "/home/airflow/.local/lib/python3.12/site-packages/airflow/cli/commands/task_command.py", line 341, in _run_raw_task
    return ti._run_raw_task(
           ^^^^^^^^^^^^^^^^^
  File "/home/airflow/.local/lib/python3.12/site-packages/airflow/utils/session.py", line 97, in wrapper
    return func(*args, session=session, **kwargs)
           ^^^^^^^^^^^^^^^^^^^^^^^^^^^^^^^^^^^^^^
  File "/home/airflow/.local/lib/python3.12/site-packages/airflow/models/taskinstance.py", line 3004, in _run_raw_task
    return _run_raw_task(
           ^^^^^^^^^^^^^^
  File "/home/airflow/.local/lib/python3.12/site-packages/airflow/models/taskinstance.py", line 273, in _run_raw_task
    TaskInstance._execute_task_with_callbacks(
  File "/home/airflow/.local/lib/python3.12/site-packages/airflow/models/taskinstance.py", line 3158, in _execute_task_with_callbacks
    result = self._execute_task(context, task_orig)
             ^^^^^^^^^^^^^^^^^^^^^^^^^^^^^^^^^^^^^^
  File "/home/airflow/.local/lib/python3.12/site-packages/airflow/models/taskinstance.py", line 3182, in _execute_task
    return _execute_task(self, context, task_orig)
           ^^^^^^^^^^^^^^^^^^^^^^^^^^^^^^^^^^^^^^^
  File "/home/airflow/.local/lib/python3.12/site-packages/airflow/models/taskinstance.py", line 767, in _execute_task
    result = _execute_callable(context=context, **execute_callable_kwargs)
             ^^^^^^^^^^^^^^^^^^^^^^^^^^^^^^^^^^^^^^^^^^^^^^^^^^^^^^^^^^^^^
  File "/home/airflow/.local/lib/python3.12/site-packages/airflow/models/taskinstance.py", line 733, in _execute_callable
    return ExecutionCallableRunner(
           ^^^^^^^^^^^^^^^^^^^^^^^^
  File "/home/airflow/.local/lib/python3.12/site-packages/airflow/utils/operator_helpers.py", line 252, in run
    return self.func(*args, **kwargs)
           ^^^^^^^^^^^^^^^^^^^^^^^^^^
  File "/home/airflow/.local/lib/python3.12/site-packages/airflow/models/baseoperator.py", line 406, in wrapper
    return func(self, *args, **kwargs)
           ^^^^^^^^^^^^^^^^^^^^^^^^^^^
  File "/home/airflow/.local/lib/python3.12/site-packages/airflow/operators/python.py", line 238, in execute
    return_value = self.execute_callable()
                   ^^^^^^^^^^^^^^^^^^^^^^^
  File "/home/airflow/.local/lib/python3.12/site-packages/airflow/operators/python.py", line 256, in execute_callable
    return runner.run(*self.op_args, **self.op_kwargs)
           ^^^^^^^^^^^^^^^^^^^^^^^^^^^^^^^^^^^^^^^^^^^
  File "/home/airflow/.local/lib/python3.12/site-packages/airflow/utils/operator_helpers.py", line 252, in run
    return self.func(*args, **kwargs)
           ^^^^^^^^^^^^^^^^^^^^^^^^^^
  File "/opt/airflow/dags/src/download_data.py", line 68, in clean_temp1
    shutil.rmtree(folder_path)
  File "/usr/local/lib/python3.12/shutil.py", line 759, in rmtree
    _rmtree_safe_fd(stack, onexc)
  File "/usr/local/lib/python3.12/shutil.py", line 703, in _rmtree_safe_fd
    onexc(func, path, err)
  File "/usr/local/lib/python3.12/shutil.py", line 700, in _rmtree_safe_fd
    onexc(os.unlink, fullname, err)
  File "/usr/local/lib/python3.12/shutil.py", line 698, in _rmtree_safe_fd
    os.unlink(entry.name, dir_fd=topfd)
FileNotFoundError: [Errno 2] No such file or directory: 'Data/temp1'
[2024-11-03T17:07:17.422+0000] {local_task_job_runner.py:266} INFO - Task exited with return code 1
[2024-11-03T17:07:17.432+0000] {taskinstance.py:3900} INFO - 0 downstream tasks scheduled from follow-on schedule check
[2024-11-03T17:07:17.432+0000] {local_task_job_runner.py:245} INFO - ::endgroup::
