[2024-10-30T20:06:23.472+0000] {local_task_job_runner.py:123} INFO - ::group::Pre task execution logs
[2024-10-30T20:06:23.478+0000] {taskinstance.py:2612} INFO - Dependencies all met for dep_context=non-requeueable deps ti=<TaskInstance: data_pipeline.db_to_schema manual__2024-10-30T20:05:46.293361+00:00 [queued]>
[2024-10-30T20:06:23.481+0000] {taskinstance.py:2612} INFO - Dependencies all met for dep_context=requeueable deps ti=<TaskInstance: data_pipeline.db_to_schema manual__2024-10-30T20:05:46.293361+00:00 [queued]>
[2024-10-30T20:06:23.481+0000] {taskinstance.py:2865} INFO - Starting attempt 2 of 2
[2024-10-30T20:06:23.485+0000] {taskinstance.py:2888} INFO - Executing <Task(PythonOperator): db_to_schema> on 2024-10-30 20:05:46.293361+00:00
[2024-10-30T20:06:23.490+0000] {warnings.py:112} WARNING - /home/***/.local/lib/python3.12/site-packages/***/task/task_runner/standard_task_runner.py:70: DeprecationWarning: This process (pid=145) is multi-threaded, use of fork() may lead to deadlocks in the child.
  pid = os.fork()

[2024-10-30T20:06:23.491+0000] {standard_task_runner.py:72} INFO - Started process 147 to run task
[2024-10-30T20:06:23.491+0000] {standard_task_runner.py:104} INFO - Running: ['***', 'tasks', 'run', 'data_pipeline', 'db_to_schema', 'manual__2024-10-30T20:05:46.293361+00:00', '--job-id', '100', '--raw', '--subdir', 'DAGS_FOLDER/***.py', '--cfg-path', '/tmp/tmphczucawx']
[2024-10-30T20:06:23.492+0000] {standard_task_runner.py:105} INFO - Job 100: Subtask db_to_schema
[2024-10-30T20:06:23.514+0000] {task_command.py:467} INFO - Running <TaskInstance: data_pipeline.db_to_schema manual__2024-10-30T20:05:46.293361+00:00 [running]> on host 6bca134bba56
[2024-10-30T20:06:23.547+0000] {taskinstance.py:3131} INFO - Exporting env vars: AIRFLOW_CTX_DAG_OWNER='your_name' AIRFLOW_CTX_DAG_ID='data_pipeline' AIRFLOW_CTX_TASK_ID='db_to_schema' AIRFLOW_CTX_EXECUTION_DATE='2024-10-30T20:05:46.293361+00:00' AIRFLOW_CTX_TRY_NUMBER='2' AIRFLOW_CTX_DAG_RUN_ID='manual__2024-10-30T20:05:46.293361+00:00'
[2024-10-30T20:06:23.548+0000] {taskinstance.py:731} INFO - ::endgroup::
[2024-10-30T20:06:25.678+0000] {taskinstance.py:3310} ERROR - Task failed with exception
Traceback (most recent call last):
  File "/home/airflow/.local/lib/python3.12/site-packages/sqlalchemy/engine/base.py", line 1094, in _commit_impl
    self.engine.dialect.do_commit(self.connection)
  File "/home/airflow/.local/lib/python3.12/site-packages/sqlalchemy/engine/default.py", line 686, in do_commit
    dbapi_connection.commit()
  File "/home/airflow/.local/lib/python3.12/site-packages/pg8000/dbapi.py", line 688, in commit
    self.execute_unnamed("commit")
  File "/home/airflow/.local/lib/python3.12/site-packages/pg8000/core.py", line 715, in execute_unnamed
    self.handle_messages(context)
  File "/home/airflow/.local/lib/python3.12/site-packages/pg8000/core.py", line 835, in handle_messages
    raise context.error
pg8000.exceptions.InterfaceError: in failed transaction block

The above exception was the direct cause of the following exception:

Traceback (most recent call last):
  File "/home/airflow/.local/lib/python3.12/site-packages/airflow/models/taskinstance.py", line 767, in _execute_task
    result = _execute_callable(context=context, **execute_callable_kwargs)
             ^^^^^^^^^^^^^^^^^^^^^^^^^^^^^^^^^^^^^^^^^^^^^^^^^^^^^^^^^^^^^
  File "/home/airflow/.local/lib/python3.12/site-packages/airflow/models/taskinstance.py", line 733, in _execute_callable
    return ExecutionCallableRunner(
           ^^^^^^^^^^^^^^^^^^^^^^^^
  File "/home/airflow/.local/lib/python3.12/site-packages/airflow/utils/operator_helpers.py", line 252, in run
    return self.func(*args, **kwargs)
           ^^^^^^^^^^^^^^^^^^^^^^^^^^
  File "/home/airflow/.local/lib/python3.12/site-packages/airflow/models/baseoperator.py", line 406, in wrapper
    return func(self, *args, **kwargs)
           ^^^^^^^^^^^^^^^^^^^^^^^^^^^
  File "/home/airflow/.local/lib/python3.12/site-packages/airflow/operators/python.py", line 238, in execute
    return_value = self.execute_callable()
                   ^^^^^^^^^^^^^^^^^^^^^^^
  File "/home/airflow/.local/lib/python3.12/site-packages/airflow/operators/python.py", line 256, in execute_callable
    return runner.run(*self.op_args, **self.op_kwargs)
           ^^^^^^^^^^^^^^^^^^^^^^^^^^^^^^^^^^^^^^^^^^^
  File "/home/airflow/.local/lib/python3.12/site-packages/airflow/utils/operator_helpers.py", line 252, in run
    return self.func(*args, **kwargs)
           ^^^^^^^^^^^^^^^^^^^^^^^^^^
  File "/opt/airflow/dags/src/db_to_schema.py", line 15, in db_to_schema
    with engine.begin() as connection:
         ^^^^^^^^^^^^^^
  File "/home/airflow/.local/lib/python3.12/site-packages/sqlalchemy/engine/base.py", line 3110, in __exit__
    self.transaction.__exit__(type_, value, traceback)
  File "/home/airflow/.local/lib/python3.12/site-packages/sqlalchemy/engine/util.py", line 235, in __exit__
    with util.safe_reraise():
         ^^^^^^^^^^^^^^^^^^^
  File "/home/airflow/.local/lib/python3.12/site-packages/sqlalchemy/util/langhelpers.py", line 70, in __exit__
    compat.raise_(
  File "/home/airflow/.local/lib/python3.12/site-packages/sqlalchemy/util/compat.py", line 211, in raise_
    raise exception
  File "/home/airflow/.local/lib/python3.12/site-packages/sqlalchemy/engine/util.py", line 233, in __exit__
    self.commit()
  File "/home/airflow/.local/lib/python3.12/site-packages/sqlalchemy/engine/base.py", line 2469, in commit
    self._do_commit()
  File "/home/airflow/.local/lib/python3.12/site-packages/sqlalchemy/engine/base.py", line 2659, in _do_commit
    self._connection_commit_impl()
  File "/home/airflow/.local/lib/python3.12/site-packages/sqlalchemy/engine/base.py", line 2630, in _connection_commit_impl
    self.connection._commit_impl()
  File "/home/airflow/.local/lib/python3.12/site-packages/sqlalchemy/engine/base.py", line 1096, in _commit_impl
    self._handle_dbapi_exception(e, None, None, None, None)
  File "/home/airflow/.local/lib/python3.12/site-packages/sqlalchemy/engine/base.py", line 2134, in _handle_dbapi_exception
    util.raise_(
  File "/home/airflow/.local/lib/python3.12/site-packages/sqlalchemy/util/compat.py", line 211, in raise_
    raise exception
  File "/home/airflow/.local/lib/python3.12/site-packages/sqlalchemy/engine/base.py", line 1094, in _commit_impl
    self.engine.dialect.do_commit(self.connection)
  File "/home/airflow/.local/lib/python3.12/site-packages/sqlalchemy/engine/default.py", line 686, in do_commit
    dbapi_connection.commit()
  File "/home/airflow/.local/lib/python3.12/site-packages/pg8000/dbapi.py", line 688, in commit
    self.execute_unnamed("commit")
  File "/home/airflow/.local/lib/python3.12/site-packages/pg8000/core.py", line 715, in execute_unnamed
    self.handle_messages(context)
  File "/home/airflow/.local/lib/python3.12/site-packages/pg8000/core.py", line 835, in handle_messages
    raise context.error
sqlalchemy.exc.InterfaceError: (pg8000.exceptions.InterfaceError) in failed transaction block
(Background on this error at: https://sqlalche.me/e/14/rvf5)
[2024-10-30T20:06:25.694+0000] {taskinstance.py:1225} INFO - Marking task as FAILED. dag_id=data_pipeline, task_id=db_to_schema, run_id=manual__2024-10-30T20:05:46.293361+00:00, execution_date=20241030T200546, start_date=20241030T200623, end_date=20241030T200625
[2024-10-30T20:06:25.703+0000] {taskinstance.py:340} INFO - ::group::Post task execution logs
[2024-10-30T20:06:25.703+0000] {standard_task_runner.py:124} ERROR - Failed to execute job 100 for task db_to_schema ((pg8000.exceptions.InterfaceError) in failed transaction block
(Background on this error at: https://sqlalche.me/e/14/rvf5); 147)
Traceback (most recent call last):
  File "/home/airflow/.local/lib/python3.12/site-packages/sqlalchemy/engine/base.py", line 1094, in _commit_impl
    self.engine.dialect.do_commit(self.connection)
  File "/home/airflow/.local/lib/python3.12/site-packages/sqlalchemy/engine/default.py", line 686, in do_commit
    dbapi_connection.commit()
  File "/home/airflow/.local/lib/python3.12/site-packages/pg8000/dbapi.py", line 688, in commit
    self.execute_unnamed("commit")
  File "/home/airflow/.local/lib/python3.12/site-packages/pg8000/core.py", line 715, in execute_unnamed
    self.handle_messages(context)
  File "/home/airflow/.local/lib/python3.12/site-packages/pg8000/core.py", line 835, in handle_messages
    raise context.error
pg8000.exceptions.InterfaceError: in failed transaction block

The above exception was the direct cause of the following exception:

Traceback (most recent call last):
  File "/home/airflow/.local/lib/python3.12/site-packages/airflow/task/task_runner/standard_task_runner.py", line 117, in _start_by_fork
    ret = args.func(args, dag=self.dag)
          ^^^^^^^^^^^^^^^^^^^^^^^^^^^^^
  File "/home/airflow/.local/lib/python3.12/site-packages/airflow/cli/cli_config.py", line 49, in command
    return func(*args, **kwargs)
           ^^^^^^^^^^^^^^^^^^^^^
  File "/home/airflow/.local/lib/python3.12/site-packages/airflow/utils/cli.py", line 115, in wrapper
    return f(*args, **kwargs)
           ^^^^^^^^^^^^^^^^^^
  File "/home/airflow/.local/lib/python3.12/site-packages/airflow/cli/commands/task_command.py", line 483, in task_run
    task_return_code = _run_task_by_selected_method(args, _dag, ti)
                       ^^^^^^^^^^^^^^^^^^^^^^^^^^^^^^^^^^^^^^^^^^^^
  File "/home/airflow/.local/lib/python3.12/site-packages/airflow/cli/commands/task_command.py", line 256, in _run_task_by_selected_method
    return _run_raw_task(args, ti)
           ^^^^^^^^^^^^^^^^^^^^^^^
  File "/home/airflow/.local/lib/python3.12/site-packages/airflow/cli/commands/task_command.py", line 341, in _run_raw_task
    return ti._run_raw_task(
           ^^^^^^^^^^^^^^^^^
  File "/home/airflow/.local/lib/python3.12/site-packages/airflow/utils/session.py", line 97, in wrapper
    return func(*args, session=session, **kwargs)
           ^^^^^^^^^^^^^^^^^^^^^^^^^^^^^^^^^^^^^^
  File "/home/airflow/.local/lib/python3.12/site-packages/airflow/models/taskinstance.py", line 3004, in _run_raw_task
    return _run_raw_task(
           ^^^^^^^^^^^^^^
  File "/home/airflow/.local/lib/python3.12/site-packages/airflow/models/taskinstance.py", line 273, in _run_raw_task
    TaskInstance._execute_task_with_callbacks(
  File "/home/airflow/.local/lib/python3.12/site-packages/airflow/models/taskinstance.py", line 3158, in _execute_task_with_callbacks
    result = self._execute_task(context, task_orig)
             ^^^^^^^^^^^^^^^^^^^^^^^^^^^^^^^^^^^^^^
  File "/home/airflow/.local/lib/python3.12/site-packages/airflow/models/taskinstance.py", line 3182, in _execute_task
    return _execute_task(self, context, task_orig)
           ^^^^^^^^^^^^^^^^^^^^^^^^^^^^^^^^^^^^^^^
  File "/home/airflow/.local/lib/python3.12/site-packages/airflow/models/taskinstance.py", line 767, in _execute_task
    result = _execute_callable(context=context, **execute_callable_kwargs)
             ^^^^^^^^^^^^^^^^^^^^^^^^^^^^^^^^^^^^^^^^^^^^^^^^^^^^^^^^^^^^^
  File "/home/airflow/.local/lib/python3.12/site-packages/airflow/models/taskinstance.py", line 733, in _execute_callable
    return ExecutionCallableRunner(
           ^^^^^^^^^^^^^^^^^^^^^^^^
  File "/home/airflow/.local/lib/python3.12/site-packages/airflow/utils/operator_helpers.py", line 252, in run
    return self.func(*args, **kwargs)
           ^^^^^^^^^^^^^^^^^^^^^^^^^^
  File "/home/airflow/.local/lib/python3.12/site-packages/airflow/models/baseoperator.py", line 406, in wrapper
    return func(self, *args, **kwargs)
           ^^^^^^^^^^^^^^^^^^^^^^^^^^^
  File "/home/airflow/.local/lib/python3.12/site-packages/airflow/operators/python.py", line 238, in execute
    return_value = self.execute_callable()
                   ^^^^^^^^^^^^^^^^^^^^^^^
  File "/home/airflow/.local/lib/python3.12/site-packages/airflow/operators/python.py", line 256, in execute_callable
    return runner.run(*self.op_args, **self.op_kwargs)
           ^^^^^^^^^^^^^^^^^^^^^^^^^^^^^^^^^^^^^^^^^^^
  File "/home/airflow/.local/lib/python3.12/site-packages/airflow/utils/operator_helpers.py", line 252, in run
    return self.func(*args, **kwargs)
           ^^^^^^^^^^^^^^^^^^^^^^^^^^
  File "/opt/airflow/dags/src/db_to_schema.py", line 15, in db_to_schema
    with engine.begin() as connection:
         ^^^^^^^^^^^^^^
  File "/home/airflow/.local/lib/python3.12/site-packages/sqlalchemy/engine/base.py", line 3110, in __exit__
    self.transaction.__exit__(type_, value, traceback)
  File "/home/airflow/.local/lib/python3.12/site-packages/sqlalchemy/engine/util.py", line 235, in __exit__
    with util.safe_reraise():
         ^^^^^^^^^^^^^^^^^^^
  File "/home/airflow/.local/lib/python3.12/site-packages/sqlalchemy/util/langhelpers.py", line 70, in __exit__
    compat.raise_(
  File "/home/airflow/.local/lib/python3.12/site-packages/sqlalchemy/util/compat.py", line 211, in raise_
    raise exception
  File "/home/airflow/.local/lib/python3.12/site-packages/sqlalchemy/engine/util.py", line 233, in __exit__
    self.commit()
  File "/home/airflow/.local/lib/python3.12/site-packages/sqlalchemy/engine/base.py", line 2469, in commit
    self._do_commit()
  File "/home/airflow/.local/lib/python3.12/site-packages/sqlalchemy/engine/base.py", line 2659, in _do_commit
    self._connection_commit_impl()
  File "/home/airflow/.local/lib/python3.12/site-packages/sqlalchemy/engine/base.py", line 2630, in _connection_commit_impl
    self.connection._commit_impl()
  File "/home/airflow/.local/lib/python3.12/site-packages/sqlalchemy/engine/base.py", line 1096, in _commit_impl
    self._handle_dbapi_exception(e, None, None, None, None)
  File "/home/airflow/.local/lib/python3.12/site-packages/sqlalchemy/engine/base.py", line 2134, in _handle_dbapi_exception
    util.raise_(
  File "/home/airflow/.local/lib/python3.12/site-packages/sqlalchemy/util/compat.py", line 211, in raise_
    raise exception
  File "/home/airflow/.local/lib/python3.12/site-packages/sqlalchemy/engine/base.py", line 1094, in _commit_impl
    self.engine.dialect.do_commit(self.connection)
  File "/home/airflow/.local/lib/python3.12/site-packages/sqlalchemy/engine/default.py", line 686, in do_commit
    dbapi_connection.commit()
  File "/home/airflow/.local/lib/python3.12/site-packages/pg8000/dbapi.py", line 688, in commit
    self.execute_unnamed("commit")
  File "/home/airflow/.local/lib/python3.12/site-packages/pg8000/core.py", line 715, in execute_unnamed
    self.handle_messages(context)
  File "/home/airflow/.local/lib/python3.12/site-packages/pg8000/core.py", line 835, in handle_messages
    raise context.error
sqlalchemy.exc.InterfaceError: (pg8000.exceptions.InterfaceError) in failed transaction block
(Background on this error at: https://sqlalche.me/e/14/rvf5)
[2024-10-30T20:06:25.726+0000] {local_task_job_runner.py:266} INFO - Task exited with return code 1
[2024-10-30T20:06:25.737+0000] {taskinstance.py:3900} INFO - 0 downstream tasks scheduled from follow-on schedule check
[2024-10-30T20:06:25.738+0000] {local_task_job_runner.py:245} INFO - ::endgroup::
